Workbook

Sheet Sheet1
A1: # | B1: Document Number | C1: Numerator | D1: Mobile | E1: Creation Date | F1: Customer/Vendor Code | G1: Customer/Vendor Name | H1: BPChannel | I1: Item Sub Group | J1: Inventory UoM | K1: Quantity | L1: SPC Quantity M2 | M1: Cancel Status
A2: 1 | B2: 583005049 | C2: 35743 | D2: 09131616215 | E2: 2026/08/23 | F2: 20000088 | G2: مرتضی دقاقی | H2: B2W | I2: موکت | J2: مترمربع | K2: 90 | L2: 0 | M2: Delivery
A3: 2 | B3: 583005054 | C3: 35749 | D3: 09177159314 | E3: 2026/08/23 | F3: 20000074 | G3: علیرضا الوانچی | H3: B2W | I3: کالیته | J3: بسته | K3: 10 | L3: 0 | M3: Delivery
A4: 3 | B4: 583005013 | C4: 35692 | D4: 09133596911 | E4: 2026/08/23 | F4: 20001232 | G4: محمدهادی دهقان هراتی | H4: B2W | I4: موکت | J4: مترمربع | K4: 540 | L4: 0 | M4: Delivery
A5: 4 | B5: 583005056 | C5: 35754 | D5: 09161186344 | E5: 2026/08/23 | F5: 20000120 | G5: شهرام مقدم | H5: B2W | I5: موکت | J5: مترمربع | K5: 51 | L5: 0 | M5: Delivery
A6: 5 | B6: 583005024 | C6: 35708 | D6: 09126002426 | E6: 2026/08/23 | F6: 20000140 | G6: محسن خراسانی | H6: B2W | I6: پادری | J6: بسته | K6: 195 | L6: 0 | M6: Delivery
A7: 6 | B7: 583005045 | C7: 35739 | D7: 09189273078 | E7: 2026/08/23 | F7: 20001222 | G7: بهروز نوره | H7: B2W | I7: موکت | J7: مترمربع | K7: 90 | L7: 0 | M7: Delivery
A8: 7 | B8: 583005005 | C8: 35680 | D8: 09017801145 | E8: 2026/08/23 | F8: 20000125 | G8: پازیرتزیین رشت (ابوالحسن خسته دل) | H8: B2W | I8: موکت | J8: مترمربع | K8: 9 | L8: 0 | M8: Delivery
A9: 8 | B9: 583005048 | C9: 35742 | D9: 09131616215 | E9: 2026/08/23 | F9: 20000088 | G9: مرتضی دقاقی | H9: B2W | I9: کالیته | J9: بسته | K9: 2 | L9: 0 | M9: Delivery
A10: 9 | B10: 583005014 | C10: 35693 | D10: 09133596911 | E10: 2026/08/23 | F10: 20001232 | G10: محمدهادی دهقان هراتی | H10: B2W | I10: پادری | J10: بسته | K10: 5 | L10: 0 | M10: Delivery
A11: 10 | B11: 583005025 | C11: 35709 | D11: 09173751074 | E11: 2026/08/23 | F11: 20000132 | G11: حمید میرشکاری(حبیب میرشکاری) | H11: B2W | I11: موکت | J11: مترمربع | K11: 252 | L11: 0 | M11: Delivery
A12: 11 | B12: 583005031 | C12: 35722 | D12: 09121061239 | E12: 2026/08/23 | F12: 20000045 | G12: مهدی اکبری نصیری | H12: B2W | I12: موکت | J12: مترمربع | K12: 48 | L12: 0 | M12: Delivery
A13: 12 | B13: 583005026 | C13: 35711 | D13: 09132775393 | E13: 2026/08/23 | F13: 20000150 | G13: عباس وطن خواه | H13: B2W | I13: موکت | J13: مترمربع | K13: 1800 | L13: 0 | M13: Delivery
... A94: 93 | B94: 583005157 | C94: 35895 | D94: 09111434182 | E94: 2026/08/25 | F94: 20000060 | G94: حسن فراسمی | H94: B2W | I94: موکت | J94: مترمربع | K94: 24 | L94: 0 | M94: Delivery
A95: 94 | B95: 583005136 | C95: 35868 | E95: 2026/08/25 | F95: 20001589 | G95: نمایندگی الوانچی(محمدرضا الوانچی) | H95: B2W | I95: SPC PACK | J95: Pack 1.77 8Ea | K95: 1344 | L95: 2378.88 | M95: Delivery
A96: 95 | B96: 583005166 | C96: 35904 | D96: 09121080808 | E96: 2026/08/25 | F96: 20000047 | G96: محسن مصطفایی | H96: B2W | I96: موکت | J96: مترمربع | K96: 90 | L96: 0 | M96: Delivery
A97: 96 | B97: 583005140 | C97: 35873 | D97: 09125657543 | E97: 2026/08/25 | F97: 20000183 | G97: رضا حسین ساریخانی | H97: B2W | I97: موکت | J97: مترمربع | K97: 90 | L97: 0 | M97: Delivery
A98: 97 | B98: 583005152 | C98: 35889 | D98: 09124310140 | E98: 2026/08/25 | F98: 20000518 | G98: امیر آقایی | H98: B2W | I98: SPC PACK | J98: Pack 1.77 8Ea | K98: 40 | L98: 70.8 | M98: Delivery
A99: 98 | B99: 583005122 | C99: 35850 | D99: 09123869198 | E99: 2026/08/25 | F99: 20000065 | G99: دنیای تجارت زیبا (بهروز اسدی اربابی) | H99: B2W | I99: لمینت | J99: بسته | K99: 240 | L99: 0 | M99: Delivery
A100: 99 | B100: 583005179 | C100: 35917 | D100: 09351687371 | E100: 2026/08/25 | F100: 20000145 | G100: غلامرضا روایی(مصطفی روایی) | H100: B2W | I100: موکت | J100: مترمربع | K100: 714 | L100: 0 | M100: Delivery
A101: 100 | B101: 583005161 | C101: 35899 | D101: 09147703634 | E101: 2026/08/25 | F101: 20001246 | G101: بهراد نجفی آقزیارت(براتعلی نجفی آقزیارت) | H101: B2W | I101: کالیته | J101: بسته | K101: 5 | L101: 0 | M101: Delivery
A102: 101 | B102: 583005173 | C102: 35911 | D102: 09121727320 | E102: 2026/08/25 | F102: 20000112 | G102: حسن گلزاری | H102: B2W | I102: کالیته | J102: عدد | K102: 1 | L102: 0 | M102: Delivery
A103: 102 | B103: 583005173 | C103: 35911 | D103: 09121727320 | E103: 2026/08/25 | F103: 20000112 | G103: حسن گلزاری | H103: B2W | I103: کالیته | J103: بسته | K103: 5 | L103: 0 | M103: Delivery
A104: 103 | B104: 583005117 | C104: 35841 | D104: 09351687371 | E104: 2026/08/25 | F104: 20000145 | G104: غلامرضا روایی(مصطفی روایی) | H104: B2W | I104: کالیته | J104: بسته | K104: 3 | L104: 0 | M104: Delivery
A105: 104 | B105: 583005138 | C105: 35870 | E105: 2026/08/25 | F105: 20001589 | G105: نمایندگی الوانچی(محمدرضا الوانچی) | H105: B2W | I105: کالیته | J105: بسته | K105: 8 | L105: 0 | M105: Delivery
A106: 105 | B106: 583005163 | C106: 35901 | D106: 09033952047 | E106: 2026/08/25 | F106: 20000118 | G106: محمد حسین بیدار بخت(سعید بیدار بخت) | H106: B2W | I106: موکت | J106: مترمربع | K106: 36 | L106: 0 | M106: Delivery
A107: 106 | B107: 583005149 | C107: 35886 | D107: 09161186344 | E107: 2026/08/25 | F107: 20000120 | G107: شهرام مقدم | H107: B2W | I107: موکت | J107: مترمربع | K107: 111 | L107: 0 | M107: Delivery
A108: 107 | B108: 583005180 | C108: 35918 | D108: 09351687371 | E108: 2026/08/25 | F108: 20000145 | G108: غلامرضا روایی(مصطفی روایی) | H108: B2W | I108: کالیته | J108: بسته | K108: 16 | L108: 0 | M108: Delivery
A109: 108 | B109: 583005163 | C109: 35901 | D109: 09033952047 | E109: 2026/08/25 | F109: 20000118 | G109: محمد حسین بیدار بخت(سعید بیدار بخت) | H109: B2W | I109: موکت | J109: مترمربع | K109: 45 | L109: 0 | M109: Delivery
A110: 109 | B110: 583005163 | C110: 35901 | D110: 09033952047 | E110: 2026/08/25 | F110: 20000118 | G110: محمد حسین بیدار بخت(سعید بیدار بخت) | H110: B2W | I110: موکت | J110: مترمربع | K110: 21 | L110: 0 | M110: Delivery
A111: 110 | B111: 583005134 | C111: 35866 | D111: 09121826803 | E111: 2026/08/25 | F111: 20001224 | G111: کریم طهماسبی | H111: B2W | I111: موکت | J111: مترمربع | K111: 252 | L111: 0 | M111: Delivery
A112: 111 | B112: 583005172 | C112: 35910 | D112: 09394160993 | E112: 2026/08/25 | F112: 20000184 | G112: سید رضا حسینی | H112: B2W | I112: کالیته | J112: بسته | K112: 11 | L112: 0 | M112: Delivery
A113: 112 | B113: 583005174 | C113: 35912 | D113: 09366769020 | E113: 2026/08/25 | F113: 20000176 | G113: آرش ایرانپور | H113: B2W | I113: موکت | J113: مترمربع | K113: 30 | L113: 0 | M113: Delivery
A114: 113 | B114: 583005145 | C114: 35881 | D114: 09143013314 | E114: 2026/08/25 | F114: 20001619 | G114: جواد باقری افشرد | H114: B2W | I114: پادری | J114: بسته | K114: 15 | L114: 0 | M114: Delivery
A115: 114 | B115: 583005165 | C115: 35903 | D115: 09166612445 | E115: 2026/08/25 | F115: 20000084 | G115: محسن رشیدی | H115: B2W | I115: موکت | J115: مترمربع | K115: 225 | L115: 0 | M115: Delivery
A116: 115 | B116: 583005127 | C116: 35856 | D116: 09122886748 | E116: 2026/08/25 | F116: 20000010 | G116: فرادید رها(شهرام صلح میرزایی) | H116: B2W | I116: موکت | J116: مترمربع | K116: 2997 | L116: 0 | M116: Delivery
A117: 116 | B117: 583005127 | C117: 35856 | D117: 09122886748 | E117: 2026/08/25 | F117: 20000010 | G117: فرادید رها(شهرام صلح میرزایی) | H117: B2W | I117: موکت | J117: مترمربع | K117: 180 | L117: 0 | M117: Delivery
... A1145: 1144 | B1145: 583006635 | C1145: 37915 | D1145: 09394160993 | E1145: 2026/09/17 | F1145: 20000184 | G1145: سید رضا حسینی | H1145: B2W | I1145: موکت | J1145: مترمربع | K1145: 576 | L1145: 0 | M1145: Delivery
A1146: 1145 | B1146: 583006622 | C1146: 37901 | E1146: 2026/09/17 | F1146: 20001589 | G1146: نمایندگی الوانچی(محمدرضا الوانچی) | H1146: B2W | I1146: کالیته | J1146: بسته | K1146: 10 | L1146: 0 | M1146: Delivery
A1147: 1146 | B1147: 583006628 | C1147: 37908 | D1147: 09394160993 | E1147: 2026/09/17 | F1147: 20000184 | G1147: سید رضا حسینی | H1147: B2W | I1147: پادری | J1147: بسته | K1147: 7 | L1147: 0 | M1147: Delivery
...

Sheet Data
A1: # | B1: Document Number | C1: Numerator | D1: Mobile | E1: Creation Date | F1: Customer/Vendor Code | G1: Customer/Vendor Name | H1: BPChannel | I1: Item Sub Group | J1: Inventory UoM | K1: Quantity | L1: SPC Quantity M2 | M1: Cancel Status
A2: 160 | B2: 583005208 | C2: 35965 | D2: 09113711382 | E2: 2026/08/26 | F2: 20000001 | G2: علی احمدی | H2: B2W | I2: موکت | J2: مترمربع | K2: 12 | L2: 0 | M2: Delivery | N2: =L2/500 -> 0 | P2: =K2/800 -> 0.015
A3: 640 | B3: 583005898 | C3: 36947 | D3: 09113711382 | E3: 2026/09/08 | F3: 20000001 | G3: علی احمدی | H3: B2W | I3: موکت | J3: مترمربع | K3: 69 | L3: 0 | M3: Delivery | N3: =L3/500 -> 0 | P3: =K3/800 -> 0.08625
A4: 1383 | B4: 583006908 | C4: 38285 | D4: 09113711382 | E4: 2026/09/21 | F4: 20000001 | G4: علی احمدی | H4: B2W | I4: موکت | J4: مترمربع | K4: 36 | L4: 0 | M4: Delivery | N4: =L4/500 -> 0 | P4: =K4/800 -> 0.045
A5: 1384 | B5: 583006908 | C5: 38285 | D5: 09113711382 | E5: 2026/09/21 | F5: 20000001 | G5: علی احمدی | H5: B2W | I5: موکت | J5: مترمربع | K5: 144 | L5: 0 | M5: Delivery | N5: =L5/500 -> 0 | P5: =K5/800 -> 0.18
A6: 1385 | B6: 583006908 | C6: 38285 | D6: 09113711382 | E6: 2026/09/21 | F6: 20000001 | G6: علی احمدی | H6: B2W | I6: موکت | J6: مترمربع | K6: 1083 | L6: 0 | M6: Delivery | N6: =L6/500 -> 0 | P6: =K6/800 -> 1.35375
A7: 264 | B7: 583005378 | C7: 36199 | D7: 09111278967 | E7: 2026/08/30 | F7: 20000003 | G7: حسن توانگری | H7: B2W | I7: موکت | J7: مترمربع | K7: 12 | L7: 0 | M7: Delivery | N7: =L7/500 -> 0 | P7: =K7/800 -> 0.015
A8: 346 | B8: 583005475 | C8: 36333 | D8: 09111278967 | E8: 2026/09/01 | F8: 20000003 | G8: حسن توانگری | H8: B2W | I8: موکت | J8: مترمربع | K8: 45 | L8: 0 | M8: Delivery | N8: =L8/500 -> 0 | P8: =K8/800 -> 0.05625
A9: 350 | B9: 583005474 | C9: 36332 | D9: 09111278967 | E9: 2026/09/01 | F9: 20000003 | G9: حسن توانگری | H9: B2W | I9: موکت | J9: مترمربع | K9: 45 | L9: 0 | M9: Delivery | N9: =L9/500 -> 0 | P9: =K9/800 -> 0.05625
A10: 370 | B10: 583005624 | C10: 36541 | D10: 09111278967 | E10: 2026/09/02 | F10: 20000003 | G10: حسن توانگری | H10: B2W | I10: موکت | J10: مترمربع | K10: 33 | L10: 0 | M10: Delivery | N10: =L10/500 -> 0 | P10: =K10/800 -> 0.04125
A11: 581 | B11: 583005834 | C11: 36841 | D11: 09111278967 | E11: 2026/09/07 | F11: 20000003 | G11: حسن توانگری | H11: B2W | I11: موکت | J11: مترمربع | K11: 21 | L11: 0 | M11: Delivery | N11: =L11/500 -> 0 | P11: =K11/800 -> 0.02625
A12: 666 | B12: 583006007 | C12: 37087 | D12: 09111278967 | E12: 2026/09/09 | F12: 20000003 | G12: حسن توانگری | H12: B2W | I12: موکت | J12: مترمربع | K12: 30 | L12: 0 | M12: Delivery | N12: =L12/500 -> 0 | P12: =K12/800 -> 0.0375
A13: 667 | B13: 583006006 | C13: 37086 | D13: 09111278967 | E13: 2026/09/09 | F13: 20000003 | G13: حسن توانگری | H13: B2W | I13: موکت | J13: مترمربع | K13: 57 | L13: 0 | M13: Delivery | N13: =L13/500 -> 0 | P13: =K13/800 -> 0.07125
... A24: 1415 | B24: 583006853 | C24: 38220 | D24: 09173155934 | E24: 2026/09/21 | F24: 20000004 | G24: داریوش عزیزی | H24: B2W | I24: موکت | J24: مترمربع | K24: 12 | L24: 0 | M24: Delivery | N24: =L24/500 -> 0 | P24: =K24/800 -> 0.015
A25: 747 | B25: 583006064 | C25: 37164 | D25: 09144142723 | E25: 2026/09/10 | F25: 20000006 | G25: صادق کیایی | H25: B2W | I25: SPC PACK | J25: Pack 1.77 8Ea | K25: 24 | L25: 42.48 | M25: Delivery | N25: =L25/500 -> 0.08496
A26: 1456 | B26: 583006920 | C26: 38312 | D26: 09144142723 | E26: 2026/09/22 | F26: 20000006 | G26: صادق کیایی | H26: B2W | I26: SPC PACK | J26: Pack 1.77 8Ea | K26: 6 | L26: 10.62 | M26: Delivery | N26: =L26/500 -> 0.02124
A27: 228 | B27: 583005317 | C27: 36118 | D27: 09144142723 | E27: 2026/08/29 | F27: 20000006 | G27: صادق کیایی | H27: B2W | I27: موکت | J27: مترمربع | K27: 90 | L27: 0 | M27: Delivery | N27: =L27/500 -> 0 | P27: =K27/800 -> 0.1125
A28: 424 | B28: 583005670 | C28: 36609 | D28: 09144142723 | E28: 2026/09/03 | F28: 20000006 | G28: صادق کیایی | H28: B2W | I28: موکت | J28: مترمربع | K28: 3 | L28: 0 | M28: Delivery | N28: =L28/500 -> 0 | P28: =K28/800 -> 0.00375
A29: 427 | B29: 583005668 | C29: 36607 | D29: 09144142723 | E29: 2026/09/03 | F29: 20000006 | G29: صادق کیایی | H29: B2W | I29: موکت | J29: مترمربع | K29: 45 | L29: 0 | M29: Delivery | N29: =L29/500 -> 0 | P29: =K29/800 -> 0.05625
A30: 428 | B30: 583005668 | C30: 36607 | D30: 09144142723 | E30: 2026/09/03 | F30: 20000006 | G30: صادق کیایی | H30: B2W | I30: موکت | J30: مترمربع | K30: 864 | L30: 0 | M30: Delivery | N30: =L30/500 -> 0 | P30: =K30/800 -> 1.08
A31: 434 | B31: 583005669 | C31: 36608 | D31: 09144142723 | E31: 2026/09/03 | F31: 20000006 | G31: صادق کیایی | H31: B2W | I31: موکت | J31: مترمربع | K31: 42 | L31: 0 | M31: Delivery | N31: =L31/500 -> 0 | P31: =K31/800 -> 0.0525
A32: 670 | B32: 583006023 | C32: 37107 | D32: 09144142723 | E32: 2026/09/09 | F32: 20000006 | G32: صادق کیایی | H32: B2W | I32: موکت | J32: مترمربع | K32: 414 | L32: 0 | M32: Delivery | N32: =L32/500 -> 0 | P32: =K32/800 -> 0.5175
A33: 671 | B33: 583006023 | C33: 37107 | D33: 09144142723 | E33: 2026/09/09 | F33: 20000006 | G33: صادق کیایی | H33: B2W | I33: موکت | J33: مترمربع | K33: 507 | L33: 0 | M33: Delivery | N33: =L33/500 -> 0 | P33: =K33/800 -> 0.63375
A34: 708 | B34: 583006046 | C34: 37140 | D34: 09144142723 | E34: 2026/09/10 | F34: 20000006 | G34: صادق کیایی | H34: B2W | I34: موکت | J34: مترمربع | K34: 108 | L34: 0 | M34: Delivery | N34: =L34/500 -> 0 | P34: =K34/800 -> 0.135
A35: 709 | B35: 583006046 | C35: 37140 | D35: 09144142723 | E35: 2026/09/10 | F35: 20000006 | G35: صادق کیایی | H35: B2W | I35: موکت | J35: مترمربع | K35: 240 | L35: 0 | M35: Delivery | N35: =L35/500 -> 0 | P35: =K35/800 -> 0.3
A36: 714 | B36: 583006045 | C36: 37139 | D36: 09144142723 | E36: 2026/09/10 | F36: 20000006 | G36: صادق کیایی | H36: B2W | I36: موکت | J36: مترمربع | K36: 90 | L36: 0 | M36: Delivery | N36: =L36/500 -> 0 | P36: =K36/800 -> 0.1125
A37: 716 | B37: 583006045 | C37: 37139 | D37: 09144142723 | E37: 2026/09/10 | F37: 20000006 | G37: صادق کیایی | H37: B2W | I37: موکت | J37: مترمربع | K37: 72 | L37: 0 | M37: Delivery | N37: =L37/500 -> 0 | P37: =K37/800 -> 0.09
A38: 717 | B38: 583006045 | C38: 37139 | D38: 09144142723 | E38: 2026/09/10 | F38: 20000006 | G38: صادق کیایی | H38: B2W | I38: موکت | J38: مترمربع | K38: 336 | L38: 0 | M38: Delivery | N38: =L38/500 -> 0 | P38: =K38/800 -> 0.42
... A46: 1186 | B46: 583006572 | C46: 37834 | D46: 09111317178 | E46: 2026/09/17 | F46: 20000008 | G46: محمد رضا محمد زاده مقدم | H46: B2W | I46: موکت | J46: مترمربع | K46: 9 | L46: 0 | M46: Delivery | N46: =L46/500 -> 0 | P46: =K46/800 -> 0.01125
A47: 156 | B47: 583005219 | C47: 35977 | D47: 09122886748 | E47: 2026/08/26 | F47: 20000010 | G47: فرادید رها(شهرام صلح میرزایی) | H47: B2W | I47: SPC PACK | J47: Pack 1.77 8Ea | K47: 28 | L47: 49.56 | M47: Delivery | N47: =L47/500 -> 0.09912
A48: 239 | B48: 583005359 | C48: 36175 | D48: 09122886748 | E48: 2026/08/30 | F48: 20000010 | G48: فرادید رها(شهرام صلح میرزایی) | H48: B2W | I48: SPC PACK | J48: Pack 1.77 8Ea | K48: 43 | L48: 76.11 | M48: Delivery | N48: =L48/500 -> 0.15222
A49: 929 | B49: 583006358 | C49: 37549 | D49: 09122886748 | E49: 2026/09/14 | F49: 20000010 | G49: فرادید رها(شهرام صلح میرزایی) | H49: B2W | I49: SPC PACK | J49: Pack 1.77 8Ea | K49: 63 | L49: 103.95 | M49: Delivery | N49: =L49/500 -> 0.2079
A50: 77 | B50: 583005142 | C50: 35876 | D50: 09122886748 | E50: 2026/08/25 | F50: 20000010 | G50: فرادید رها(شهرام صلح میرزایی) | H50: B2W | I50: موکت | J50: مترمربع | K50: 3141 | L50: 0 | M50: Delivery | N50: =L50/500 -> 0 | P50: =K50/800 -> 3.92625
A51: 78 | B51: 583005142 | C51: 35876 | D51: 09122886748 | E51: 2026/08/25 | F51: 20000010 | G51: فرادید رها(شهرام صلح میرزایی) | H51: B2W | I51: موکت | J51: مترمربع | K51: 1191 | L51: 0 | M51: Delivery | N51: =L51/500 -> 0 | P51: =K51/800 -> 1.48875
A52: 79 | B52: 583005142 | C52: 35876 | D52: 09122886748 | E52: 2026/08/25 | F52: 20000010 | G52: فرادید رها(شهرام صلح میرزایی) | H52: B2W | I52: موکت | J52: مترمربع | K52: 225 | L52: 0 | M52: Delivery | N52: =L52/500 -> 0 | P52: =K52/800 -> 0.28125
A53: 115 | B53: 583005127 | C53: 35856 | D53: 09122886748 | E53: 2026/08/25 | F53: 20000010 | G53: فرادید رها(شهرام صلح میرزایی) | H53: B2W | I53: موکت | J53: مترمربع | K53: 2997 | L53: 0 | M53: Delivery | N53: =L53/500 -> 0 | P53: =K53/800 -> 3.74625
A54: 116 | B54: 583005127 | C54: 35856 | D54: 09122886748 | E54: 2026/08/25 | F54: 20000010 | G54: فرادید رها(شهرام صلح میرزایی) | H54: B2W | I54: موکت | J54: مترمربع | K54: 180 | L54: 0 | M54: Delivery | N54: =L54/500 -> 0 | P54: =K54/800 -> 0.225
A55: 117 | B55: 583005127 | C55: 35856 | D55: 09122886748 | E55: 2026/08/25 | F55: 20000010 | G55: فرادید رها(شهرام صلح میرزایی) | H55: B2W | I55: موکت | J55: مترمربع | K55: 708 | L55: 0 | M55: Delivery | N55: =L55/500 -> 0 | P55: =K55/800 -> 0.885
A56: 213 | B56: 583005307 | C56: 36107 | D56: 09122886748 | E56: 2026/08/29 | F56: 20000010 | G56: فرادید رها(شهرام صلح میرزایی) | H56: B2W | I56: موکت | J56: مترمربع | K56: 1296 | L56: 0 | M56: Delivery | N56: =L56/500 -> 0 | P56: =K56/800 -> 1.62
A57: 214 | B57: 583005307 | C57: 36107 | D57: 09122886748 | E57: 2026/08/29 | F57: 20000010 | G57: فرادید رها(شهرام صلح میرزایی) | H57: B2W | I57: موکت | J57: مترمربع | K57: 2385 | L57: 0 | M57: Delivery | N57: =L57/500 -> 0 | P57: =K57/800 -> 2.98125
...

Sheet Report
B2: Customer/Vendor Code | C2: Customer/Vendor Name | H2: جمع پال
B3: 20000074 | C3: علیرضا الوانچی | D3: =SUMIFS(Data!N:N,Data!$F:$F,$B3) -> 0 | E3: =SUMIFS(Data!O:O,Data!$F:$F,$B3) -> 0 | F3: =SUMIFS(Data!P:P,Data!$F:$F,$B3) -> 178.26 | G3: =SUMIFS(Data!Q:Q,Data!$F:$F,$B3) -> 2.17272 | H3: =SUM(D3:G3) -> 180.43272
B4: 20000242 | C4: اهورا پود ماهان (مجتبی کریمی) | D4: =SUMIFS(Data!N:N,Data!$F:$F,$B4) -> 0 | E4: =SUMIFS(Data!O:O,Data!$F:$F,$B4) -> 0 | F4: =SUMIFS(Data!P:P,Data!$F:$F,$B4) -> 160.6875 | G4: =SUMIFS(Data!Q:Q,Data!$F:$F,$B4) -> 0 | H4: =SUM(D4:G4) -> 160.6875 | I4: Not Acceptable
B5: 20000010 | C5: فرادید رها(شهرام صلح میرزایی) | D5: =SUMIFS(Data!N:N,Data!$F:$F,$B5) -> 0.45924 | E5: =SUMIFS(Data!O:O,Data!$F:$F,$B5) -> 0 | F5: =SUMIFS(Data!P:P,Data!$F:$F,$B5) -> 73.3425 | G5: =SUMIFS(Data!Q:Q,Data!$F:$F,$B5) -> 0.81 | H5: =SUM(D5:G5) -> 74.61174
B6: 20000065 | C6: دنیای تجارت زیبا (بهروز اسدی اربابی) | D6: =SUMIFS(Data!N:N,Data!$F:$F,$B6) -> 5.15424 | E6: =SUMIFS(Data!O:O,Data!$F:$F,$B6) -> 21.36544 | F6: =SUMIFS(Data!P:P,Data!$F:$F,$B6) -> 43.53375 | G6: =SUMIFS(Data!Q:Q,Data!$F:$F,$B6) -> 0.12 | H6: =SUM(D6:G6) -> 70.17343
B7: 20000120 | C7: شهرام مقدم | D7: =SUMIFS(Data!N:N,Data!$F:$F,$B7) -> 2.89692 | E7: =SUMIFS(Data!O:O,Data!$F:$F,$B7) -> 0 | F7: =SUMIFS(Data!P:P,Data!$F:$F,$B7) -> 36.70125 | G7: =SUMIFS(Data!Q:Q,Data!$F:$F,$B7) -> 0.2388 | H7: =SUM(D7:G7) -> 39.83697
B8: 20001246 | C8: بهراد نجفی آقزیارت(براتعلی نجفی آقزیارت) | D8: =SUMIFS(Data!N:N,Data!$F:$F,$B8) -> 0 | E8: =SUMIFS(Data!O:O,Data!$F:$F,$B8) -> 0 | F8: =SUMIFS(Data!P:P,Data!$F:$F,$B8) -> 25.0575 | G8: =SUMIFS(Data!Q:Q,Data!$F:$F,$B8) -> 1.2 | H8: =SUM(D8:G8) -> 26.2575
B9: 20001301 | C9: آریا نخستین پارسه | D9: =SUMIFS(Data!N:N,Data!$F:$F,$B9) -> 0 | E9: =SUMIFS(Data!O:O,Data!$F:$F,$B9) -> 0 | F9: =SUMIFS(Data!P:P,Data!$F:$F,$B9) -> 23.31375 | G9: =SUMIFS(Data!Q:Q,Data!$F:$F,$B9) -> 0.72 | H9: =SUM(D9:G9) -> 24.03375
B10: 20000140 | C10: محسن خراسانی | D10: =SUMIFS(Data!N:N,Data!$F:$F,$B10) -> 0 | E10: =SUMIFS(Data!O:O,Data!$F:$F,$B10) -> 0 | F10: =SUMIFS(Data!P:P,Data!$F:$F,$B10) -> 18.51 | G10: =SUMIFS(Data!Q:Q,Data!$F:$F,$B10) -> 0.2796 | H10: =SUM(D10:G10) -> 18.7896
B11: 20000186 | C11: حمید امینی نجف آبادی | D11: =SUMIFS(Data!N:N,Data!$F:$F,$B11) -> 0.0795 | E11: =SUMIFS(Data!O:O,Data!$F:$F,$B11) -> 0 | F11: =SUMIFS(Data!P:P,Data!$F:$F,$B11) -> 16.3875 | G11: =SUMIFS(Data!Q:Q,Data!$F:$F,$B11) -> 0 | H11: =SUM(D11:G11) -> 16.467
B12: 20000150 | C12: عباس وطن خواه | D12: =SUMIFS(Data!N:N,Data!$F:$F,$B12) -> 0 | E12: =SUMIFS(Data!O:O,Data!$F:$F,$B12) -> 0 | F12: =SUMIFS(Data!P:P,Data!$F:$F,$B12) -> 14.8575 | G12: =SUMIFS(Data!Q:Q,Data!$F:$F,$B12) -> 0.096 | H12: =SUM(D12:G12) -> 14.9535
B13: 20000145 | C13: غلامرضا روایی(مصطفی روایی) | D13: =SUMIFS(Data!N:N,Data!$F:$F,$B13) -> 0 | E13: =SUMIFS(Data!O:O,Data!$F:$F,$B13) -> 0 | F13: =SUMIFS(Data!P:P,Data!$F:$F,$B13) -> 14.4225 | G13: =SUMIFS(Data!Q:Q,Data!$F:$F,$B13) -> 0 | H13: =SUM(D13:G13) -> 14.4225
B14: 20000237 | C14: محمد نصاری | D14: =SUMIFS(Data!N:N,Data!$F:$F,$B14) -> 0 | E14: =SUMIFS(Data!O:O,Data!$F:$F,$B14) -> 0 | F14: =SUMIFS(Data!P:P,Data!$F:$F,$B14) -> 12.76125 | G14: =SUMIFS(Data!Q:Q,Data!$F:$F,$B14) -> 0.84072 | H14: =SUM(D14:G14) -> 13.60197
B15: 20000045 | C15: مهدی اکبری نصیری | D15: =SUMIFS(Data!N:N,Data!$F:$F,$B15) -> 0 | E15: =SUMIFS(Data!O:O,Data!$F:$F,$B15) -> 0 | F15: =SUMIFS(Data!P:P,Data!$F:$F,$B15) -> 13.43625 | G15: =SUMIFS(Data!Q:Q,Data!$F:$F,$B15) -> 0 | H15: =SUM(D15:G15) -> 13.43625
B16: 20000231 | C16: اصغر صابر | D16: =SUMIFS(Data!N:N,Data!$F:$F,$B16) -> 0 | E16: =SUMIFS(Data!O:O,Data!$F:$F,$B16) -> 0 | F16: =SUMIFS(Data!P:P,Data!$F:$F,$B16) -> 11.6175 | G16: =SUMIFS(Data!Q:Q,Data!$F:$F,$B16) -> 0.24 | H16: =SUM(D16:G16) -> 11.8575
... B129: 20000146 | C129: رویا طراح داخلی | D129: =SUMIFS(Data!N:N,Data!$F:$F,$B129) -> 0.00708 | E129: =SUMIFS(Data!O:O,Data!$F:$F,$B129) -> 0 | F129: =SUMIFS(Data!P:P,Data!$F:$F,$B129) -> 0 | G129: =SUMIFS(Data!Q:Q,Data!$F:$F,$B129) -> 0 | H129: =SUM(D129:G129) -> 0.00708
